Workbook

Sheet Mode d'emploi
B2: INVENTAIRE PHYSIQUE - ECONOMAT
B3: Ofauria - feuille de comptage a imprimer ou a remplir directement dans Excel
B5: SECTION | C5: COMMENT FAIRE
B6: 1. Avant de commencer | C6: Renseignez la date, le nom du compteur et du verificateur en haut de chaque onglet de comptage. Comptez zone par zone et cochez au fur et a mesure : ne revenez jamais en arriere sur une ligne deja comptee.
B7: 2. Onglet 'Ingredients' | C7: Une ligne par ingredient de l'economat. Deux facons de saisir, au choix selon l'article : - Article en contenants (sac, seau, bidon...) : mettez le nombre de contenants PLEINS en colonne J, puis le reste (sac entame, pese sur balance) en colonne K, dans l'unite de l'article. - Article en vrac ou a la piece : laissez J vide et mettez tout le comptage en colonne K. La colonne L 'Qte comptee' se calcule toute seule : J x contenu du contenant + K.
B8: 3. Onglet 'Consommables' | C8: Emballages, produits et materiel d'entretien, petit materiel. Une seule colonne de saisie : colonne I 'Qte comptee', en pieces (ou dans l'unite indiquee).
B9: 4. Couleurs des cellules | C9: Fond JAUNE = a remplir a la main. Fond GRIS = calcule automatiquement, ne pas ecrire dedans. Fond blanc = donnee issue de l'application (theorique, prix, categorie).
B10: 5. Ecarts | C10: Ecart = Qte comptee - Stock theorique. Le stock theorique est ici volontairement mis a 0 : le comptage physique fait foi et l'ecart est donc egal a la quantite comptee. Toute ligne avec un ecart non nul apparait en rouge : justifiez-la en colonne 'Observations' (casse, perte, erreur de reception, sortie non saisie...).
B11: 6. Onglet 'Synthese' | C11: Recapitulatif automatique par famille : valeur comptee, valeur theorique et valeur de l'ecart. Rien a saisir, tout se met a jour des que vous remplissez les onglets de comptage.
B12: 7. Apres le comptage | C12: Faites signer la feuille, puis reportez les quantites comptees dans l'application (Economat > ajustement de stock) en conservant ce fichier comme piece justificative.
B14: EXEMPLE DE SAISIE (onglet Ingredients)
B15: Article | C15: Unite | D15: Contenant | E15: Contenu/contenant | F15: Stock theorique | G15: Nb contenants pleins | H15: Qte hors contenant | I15: Qte comptee | J15: Ecart
B16: Farine boulangerie | C16: kg | D16: Sac | E16: 25 | F16: 875 | G16: 34 | H16: 12.5 | I16: 34 x 25 + 12,5 -> 862,5 | J16: -12,5
B17: Beurre | C17: kg | F17: 725 | H17: 718 | I17: 718 | J17: -7
B18: Oeuf | C18: unit | F18: 3720 | H18: 3735 | I18: 3 735 | J18: +15

Sheet Ingredients
A1: INVENTAIRE ECONOMAT - INGREDIENTS ET MATIERES PREMIERES
A3: Date de l'inventaire : | B3: 06/08/2026 | D3: Comptage effectue par : | E3: Releve carnet magasin | G3: Verifie par :
A4: Fond jaune = a remplir | fond gris = calcule automatiquement | ecart non nul = ligne en rouge
A6: N° | B6: Famille | C6: Categorie | D6: Article | E6: Fournisseur | F6: Unite | G6: Contenant | H6: Contenu / contenant | I6: Stock theorique | J6: Nb contenants pleins | K6: Qte hors contenant | L6: Qte comptee | M6: Ecart | N6: PU | O6: Valeur comptee | P6: Valeur ecart | Q6: DLC la + proche | R6: Statut | S6: Observations
A7: 1 | B7: Matières premières | C7: Ingrédients > Autre | D7: Amarina | F7: unit | I7: 0 | L7: =IF(AND(J7="",K7=""),"",IF(H7="",K7,J7*H7+K7)) | M7: =IF(L7="","",L7-I7) | N7: 145 | O7: =IF(L7="","",L7*N7) | P7: =IF(M7="","",M7*N7) | R7: En stock
A8: 2 | B8: Matières premières | C8: Ingrédients > Autre | D8: Amelioruer de viennoiserie | F8: kg | I8: 0 | L8: =IF(AND(J8="",K8=""),"",IF(H8="",K8,J8*H8+K8)) | M8: =IF(L8="","",L8-I8) | N8: 20 | O8: =IF(L8="","",L8*N8) | P8: =IF(M8="","",M8*N8) | R8: En stock
A9: 3 | B9: Matières premières | C9: Ingrédients > Autre | D9: Baignoire | F9: unit | I9: 0 | L9: =IF(AND(J9="",K9=""),"",IF(H9="",K9,J9*H9+K9)) | M9: =IF(L9="","",L9-I9) | N9: 230 | O9: =IF(L9="","",L9*N9) | P9: =IF(M9="","",M9*N9) | R9: En stock
A10: 4 | B10: Matières premières | C10: Ingrédients > Autre | D10: Barbe de noire | F10: g | I10: 0 | L10: =IF(AND(J10="",K10=""),"",IF(H10="",K10,J10*H10+K10)) | M10: =IF(L10="","",L10-I10) | N10: 0.08 | O10: =IF(L10="","",L10*N10) | P10: =IF(M10="","",M10*N10) | R10: Stock a 0
A11: 5 | B11: Matières premières | C11: Ingrédients > Autre | D11: Bouillon poisson (boîte 36 cubes) | E11: Idéal | F11: unit | I11: 0 | L11: =IF(AND(J11="",K11=""),"",IF(H11="",K11,J11*H11+K11)) | M11: =IF(L11="","",L11-I11) | N11: 1.3889 | O11: =IF(L11="","",L11*N11) | P11: =IF(M11="","",M11*N11) | R11: Jamais recu
A12: 6 | B12: Matières premières | C12: Ingrédients > Autre | D12: Boules colorées | F12: unit | I12: 0 | L12: =IF(AND(J12="",K12=""),"",IF(H12="",K12,J12*H12+K12)) | M12: =IF(L12="","",L12-I12) | N12: 5 | O12: =IF(L12="","",L12*N12) | P12: =IF(M12="","",M12*N12) | R12: En stock
A13: 7 | B13: Matières premières | C13: Ingrédients > Autre | D13: Boulgour | F13: kg | I13: 0 | L13: =IF(AND(J13="",K13=""),"",IF(H13="",K13,J13*H13+K13)) | M13: =IF(L13="","",L13-I13) | N13: 7 | O13: =IF(L13="","",L13*N13) | P13: =IF(M13="","",M13*N13) | R13: Stock a 0
A14: 8 | B14: Matières premières | C14: Ingrédients > Autre | D14: Brick | F14: unit | I14: 0 | L14: =IF(AND(J14="",K14=""),"",IF(H14="",K14,J14*H14+K14)) | M14: =IF(L14="","",L14-I14) | N14: 8 | O14: =IF(L14="","",L14*N14) | P14: =IF(M14="","",M14*N14) | R14: Stock a 0
A15: 9 | B15: Matières premières | C15: Ingrédients > Autre | D15: CHOCOLAT LAIT DGF | F15: kg | I15: 0 | L15: =IF(AND(J15="",K15=""),"",IF(H15="",K15,J15*H15+K15)) | M15: =IF(L15="","",L15-I15) | N15: 103.33 | O15: =IF(L15="","",L15*N15) | P15: =IF(M15="","",M15*N15) | R15: En stock
A16: 10 | B16: Matières premières | C16: Ingrédients > Autre | D16: CHOCOLAT NOIR DGF | F16: kg | I16: 0 | L16: =IF(AND(J16="",K16=""),"",IF(H16="",K16,J16*H16+K16)) | M16: =IF(L16="","",L16-I16) | N16: 99.17 | O16: =IF(L16="","",L16*N16) | P16: =IF(M16="","",M16*N16) | R16: En stock
A17: 11 | B17: Matières premières | C17: Ingrédients > Autre | D17: COMPTE de pomme | F17: unit | I17: 0 | L17: =IF(AND(J17="",K17=""),"",IF(H17="",K17,J17*H17+K17)) | M17: =IF(L17="","",L17-I17) | N17: 0 | O17: =IF(L17="","",L17*N17) | P17: =IF(M17="","",M17*N17) | R17: Jamais recu
A18: 12 | B18: Matières premières | C18: Ingrédients > Autre | D18: COMPTE DE POMME | F18: unit | I18: 0 | L18: =IF(AND(J18="",K18=""),"",IF(H18="",K18,J18*H18+K18)) | M18: =IF(L18="","",L18-I18) | N18: 140.83 | O18: =IF(L18="","",L18*N18) | P18: =IF(M18="","",M18*N18) | R18: Stock a 0
A19: 13 | B19: Matières premières | C19: Ingrédients > Autre | D19: CREME PATISSIERE | F19: kg | I19: 0 | L19: =IF(AND(J19="",K19=""),"",IF(H19="",K19,J19*H19+K19)) | M19: =IF(L19="","",L19-I19) | N19: 9.83 | O19: =IF(L19="","",L19*N19) | P19: =IF(M19="","",M19*N19) | R19: En stock
A20: 14 | B20: Matières premières | C20: Ingrédients > Autre | D20: CURCUMA | F20: g | I20: 0 | L20: =IF(AND(J20="",K20=""),"",IF(H20="",K20,J20*H20+K20)) | M20: =IF(L20="","",L20-I20) | N20: 0.06 | O20: =IF(L20="","",L20*N20) | P20: =IF(M20="","",M20*N20) | R20: En stock
A21: 15 | B21: Matières premières | C21: Ingrédients > Autre | D21: Cacahuète | F21: g | I21: 0 | L21: =IF(AND(J21="",K21=""),"",IF(H21="",K21,J21*H21+K21)) | M21: =IF(L21="","",L21-I21) | N21: 10 | O21: =IF(L21="","",L21*N21) | P21: =IF(M21="","",M21*N21) | R21: En stock
A22: 16 | B22: Matières premières | C22: Ingrédients > Autre | D22: Café templier | F22: kg | I22: 0 | L22: =IF(AND(J22="",K22=""),"",IF(H22="",K22,J22*H22+K22)) | M22: =IF(L22="","",L22-I22) | N22: 0 | O22: =IF(L22="","",L22*N22) | P22: =IF(M22="","",M22*N22) | R22: Jamais recu
A23: 17 | B23: Matières premières | C23: Ingrédients > Autre | D23: Champignon | F23: unit | I23: 0 | L23: =IF(AND(J23="",K23=""),"",IF(H23="",K23,J23*H23+K23)) | M23: =IF(L23="","",L23-I23) | N23: 20 | O23: =IF(L23="","",L23*N23) | P23: =IF(M23="","",M23*N23) | R23: En stock
... A88: 82 | B88: Matières premières | C88: Ingrédients > Autre | D88: Purée de mangue | F88: kg | I88: 0 | L88: =IF(AND(J88="",K88=""),"",IF(H88="",K88,J88*H88+K88)) | M88: =IF(L88="","",L88-I88) | N88: 97.8 | O88: =IF(L88="","",L88*N88) | P88: =IF(M88="","",M88*N88) | R88: Stock a 0
A89: 83 | B89: Matières premières | C89: Ingrédients > Autre | D89: Purée de passion | F89: l | I89: 0 | L89: =IF(AND(J89="",K89=""),"",IF(H89="",K89,J89*H89+K89)) | M89: =IF(L89="","",L89-I89) | N89: 97.8 | O89: =IF(L89="","",L89*N89) | P89: =IF(M89="","",M89*N89) | Q89: 2027-02-03 | R89: En stock
A90: 84 | B90: Matières premières | C90: Ingrédients > Autre | D90: Purée de poire | F90: ml | I90: 0 | L90: =IF(AND(J90="",K90=""),"",IF(H90="",K90,J90*H90+K90)) | M90: =IF(L90="","",L90-I90) | N90: 0 | O90: =IF(L90="","",L90*N90) | P90: =IF(M90="","",M90*N90) | R90: Jamais recu
A91: 85 | B91: Matières premières | C91: Ingrédients > Autre | D91: Purée framboises | F91: kg | I91: 0 | L91: =IF(AND(J91="",K91=""),"",IF(H91="",K91,J91*H91+K91)) | M91: =IF(L91="","",L91-I91) | N91: 97.8 | O91: =IF(L91="","",L91*N91) | P91: =IF(M91="","",M91*N91) | R91: En stock
A92: 86 | B92: Matières premières | C92: Ingrédients > Autre | D92: Purée passion | F92: ml | I92: 0 | L92: =IF(AND(J92="",K92=""),"",IF(H92="",K92,J92*H92+K92)) | M92: =IF(L92="","",L92-I92) | N92: 0 | O92: =IF(L92="","",L92*N92) | P92: =IF(M92="","",M92*N92) | R92: Jamais recu
A93: 87 | B93: Matières premières | C93: Ingrédients > Autre | D93: Purée pomme | F93: kg | I93: 0 | L93: =IF(AND(J93="",K93=""),"",IF(H93="",K93,J93*H93+K93)) | M93: =IF(L93="","",L93-I93) | N93: 0 | O93: =IF(L93="","",L93*N93) | P93: =IF(M93="","",M93*N93) | R93: Jamais recu
A94: 88 | B94: Matières premières | C94: Ingrédients > Autre | D94: RAISIN | F94: kg | I94: 0 | K94: 20.5 | L94: =IF(AND(J94="",K94=""),"",IF(H94="",K94,J94*H94+K94)) | M94: =IF(L94="","",L94-I94) | N94: 50 | O94: =IF(L94="","",L94*N94) | P94: =IF(M94="","",M94*N94) | R94: En stock
A95: 89 | B95: Matières premières | C95: Ingrédients > Autre | D95: Roses | F95: unit | I95: 0 | L95: =IF(AND(J95="",K95=""),"",IF(H95="",K95,J95*H95+K95)) | M95: =IF(L95="","",L95-I95) | N95: 2 | O95: =IF(L95="","",L95*N95) | P95: =IF(M95="","",M95*N95) | R95: En stock
A96: 90 | B96: Matières premières | C96: Ingrédients > Autre | D96: SUCRE CASSONADE | F96: kg | I96: 0 | L96: =IF(AND(J96="",K96=""),"",IF(H96="",K96,J96*H96+K96)) | M96: =IF(L96="","",L96-I96) | N96: 40.83 | O96: =IF(L96="","",L96*N96) | P96: =IF(M96="","",M96*N96) | R96: En stock
A97: 91 | B97: Matières premières | C97: Ingrédients > Autre | D97: Salé | F97: unit | I97: 0 | L97: =IF(AND(J97="",K97=""),"",IF(H97="",K97,J97*H97+K97)) | M97: =IF(L97="","",L97-I97) | N97: 10 | O97: =IF(L97="","",L97*N97) | P97: =IF(M97="","",M97*N97) | R97: En stock
A98: 92 | B98: Matières premières | C98: Ingrédients > Autre | D98: Sapoir shaabi | F98: kg | I98: 0 | L98: =IF(AND(J98="",K98=""),"",IF(H98="",K98,J98*H98+K98)) | M98: =IF(L98="","",L98-I98) | N98: 31.5875 | O98: =IF(L98="","",L98*N98) | P98: =IF(M98="","",M98*N98) | R98: Stock a 0
A99: 93 | B99: Matières premières | C99: Ingrédients > Autre | D99: Savon liquide pour les mains | F99: unit | I99: 0 | L99: =IF(AND(J99="",K99=""),"",IF(H99="",K99,J99*H99+K99)) | M99: =IF(L99="","",L99-I99) | N99: 15 | O99: =IF(L99="","",L99*N99) | P99: =IF(M99="","",M99*N99) | R99: En stock
A100: 94 | B100: Matières premières | C100: Ingrédients > Autre | D100: Sirop de glucose | F100: g | I100: 0 | L100: =IF(AND(J100="",K100=""),"",IF(H100="",K100,J100*H100+K100)) | M100: =IF(L100="","",L100-I100) | N100: 0.024 | O100: =IF(L100="","",L100*N100) | P100: =IF(M100="","",M100*N100) | R100: En stock
A101: 95 | B101: Matières premières | C101: Ingrédients > Autre | D101: Sofat garoin | F101: kg | I101: 0 | L101: =IF(AND(J101="",K101=""),"",IF(H101="",K101,J101*H101+K101)) | M101: =IF(L101="","",L101-I101) | N101: 39.166 | O101: =IF(L101="","",L101*N101) | P101: =IF(M101="","",M101*N101) | R101: En stock
A102: 96 | B102: Matières premières | C102: Ingrédients > Autre | D102: Sucrrée | F102: unit | I102: 0 | L102: =IF(AND(J102="",K102=""),"",IF(H102="",K102,J102*H102+K102)) | M102: =IF(L102="","",L102-I102) | N102: 15 | O102: =IF(L102="","",L102*N102) | P102: =IF(M102="","",M102*N102) | R102: En stock
A103: 97 | B103: Matières premières | C103: Ingrédients > Autre | D103: Sésame blan | F103: kg | I103: 0 | L103: =IF(AND(J103="",K103=""),"",IF(H103="",K103,J103*H103+K103)) | M103: =IF(L103="","",L103-I103) | N103: 48 | O103: =IF(L103="","",L103*N103) | P103: =IF(M103="","",M103*N103) | R103: Stock a 0
A104: 98 | B104: Matières premières | C104: Ingrédients > Autre | D104: TABLETTE SIGNATURE BLANC | F104: kg | I104: 0 | L104: =IF(AND(J104="",K104=""),"",IF(H104="",K104,J104*H104+K104)) | M104: =IF(L104="","",L104-I104) | N104: 35.72 | O104: =IF(L104="","",L104*N104) | P104: =IF(M104="","",M104*N104) | R104: Stock a 0
A105: 99 | B105: Matières premières | C105: Ingrédients > Autre | D105: Tegral multigrain | F105: kg | I105: 0 | L105: =IF(AND(J105="",K105=""),"",IF(H105="",K105,J105*H105+K105)) | M105: =IF(L105="","",L105-I105) | N105: 12.408 | O105: =IF(L105="","",L105*N105) | P105: =IF(M105="","",M105*N105) | R105: En stock
A106: 100 | B106: Matières premières | C106: Ingrédients > Autre | D106: Thym | F106: kg | I106: 0 | L106: =IF(AND(J106="",K106=""),"",IF(H106="",K106,J106*H106+K106)) | M106: =IF(L106="","",L106-I106) | N106: 116 | O106: =IF(L106="","",L106*N106) | P106: =IF(M106="","",M106*N106) | R106: Jamais recu
...

Sheet Consommables
A1: INVENTAIRE ECONOMAT - EMBALLAGES, ENTRETIEN ET PETIT MATERIEL
A3: Date de l'inventaire : | D3: Comptage effectue par : | G3: Verifie par :
A4: Fond jaune = a remplir | fond gris = calcule automatiquement | ecart non nul = ligne en rouge
A6: N° | B6: Famille | C6: Categorie | D6: Article | E6: Format | F6: Fournisseur | G6: Unite | H6: Stock theorique | I6: Qte comptee | J6: Ecart | K6: PU | L6: Valeur comptee | M6: Valeur ecart | N6: Observations
A7: 1 | B7: Emballages | C7: Boites | D7: Boite à gateau | G7: unit | H7: 0 | J7: =IF(I7="","",I7-H7) | K7: 30 | L7: =IF(I7="","",I7*K7) | M7: =IF(J7="","",J7*K7)
A8: 2 | B8: Emballages | C8: Etiquettes | D8: Etiquettes | G8: unit | H8: 0 | J8: =IF(I8="","",I8-H8) | K8: 12 | L8: =IF(I8="","",I8*K8) | M8: =IF(J8="","",J8*K8)
A9: 3 | B9: Emballages | C9: Etiquettes | D9: Languette triangle | G9: unit | H9: 0 | J9: =IF(I9="","",I9-H9) | K9: 0.24 | L9: =IF(I9="","",I9*K9) | M9: =IF(J9="","",J9*K9)
A10: 4 | B10: Emballages | C10: Ficelles & Rubans | D10: CAPSULES | G10: unit | H10: 0 | J10: =IF(I10="","",I10-H10) | K10: 5 | L10: =IF(I10="","",I10*K10) | M10: =IF(J10="","",J10*K10)
A11: 5 | B11: Emballages | C11: Ficelles & Rubans | D11: Caissette 45 | G11: unit | H11: 0 | J11: =IF(I11="","",I11-H11) | K11: 30 | L11: =IF(I11="","",I11*K11) | M11: =IF(J11="","",J11*K11)
A12: 6 | B12: Emballages | C12: Ficelles & Rubans | D12: Caissette capcake | G12: unit | H12: 0 | J12: =IF(I12="","",I12-H12) | K12: 0.8 | L12: =IF(I12="","",I12*K12) | M12: =IF(J12="","",J12*K12)
A13: 7 | B13: Emballages | C13: Ficelles & Rubans | D13: Caissette muffins | G13: unit | H13: 0 | J13: =IF(I13="","",I13-H13) | K13: 28 | L13: =IF(I13="","",I13*K13) | M13: =IF(J13="","",J13*K13)
A14: 8 | B14: Emballages | C14: Ficelles & Rubans | D14: FEUILLE DE CELLOPHANE | G14: unit | H14: 0 | J14: =IF(I14="","",I14-H14) | K14: 1.5 | L14: =IF(I14="","",I14*K14) | M14: =IF(J14="","",J14*K14)
A15: 9 | B15: Emballages | C15: Ficelles & Rubans | D15: Languette | G15: unit | H15: 0 | J15: =IF(I15="","",I15-H15) | K15: 0 | L15: =IF(I15="","",I15*K15) | M15: =IF(J15="","",J15*K15)
A16: 10 | B16: Emballages | C16: Ficelles & Rubans | D16: Longuette cheese cake | G16: unit | H16: 0 | J16: =IF(I16="","",I16-H16) | K16: 0.24 | L16: =IF(I16="","",I16*K16) | M16: =IF(J16="","",J16*K16)
A17: 11 | B17: Emballages | C17: Ficelles & Rubans | D17: Longuette triangle | G17: unit | H17: 0 | J17: =IF(I17="","",I17-H17) | K17: 0.3 | L17: =IF(I17="","",I17*K17) | M17: =IF(J17="","",J17*K17)
A18: 12 | B18: Emballages | C18: Ficelles & Rubans | D18: Pévicé | G18: unit | H18: 0 | J18: =IF(I18="","",I18-H18) | K18: 180 | L18: =IF(I18="","",I18*K18) | M18: =IF(J18="","",J18*K18)
... A115: 109 | B115: Équipements & Matériel | C115: Petit matériel > Ustensiles pâtisserie | D115: Silicon trompe l'oeil mangue | G115: unit | H115: 0 | J115: =IF(I115="","",I115-H115) | K115: 170 | L115: =IF(I115="","",I115*K115) | M115: =IF(J115="","",J115*K115)
D116: TOTAL CONSOMMABLES | L116: =SUM(L7:L115) | M116: =SUM(M7:M115)

Sheet A arbitrer
A1: COMPTAGE DU CARNET - LIGNES NON REPORTEES
A2: Ces quantites ont bien ete comptees, mais l'article correspondant est ambigu dans le referentiel. Choisissez le bon article, puis saisissez la quantite dans l'onglet 'Ingredients'.
A4: Libelle du carnet | B4: Quantite comptee | C4: Pourquoi ce n'est pas reporte | D4: Articles candidats en base | E4: Article retenu
A5: Beurre | B5: 140 kg | C5: 3 articles 'Beurre' au referentiel | D5: Beurre (kg, theo 125) | Beurre (kg, theo 600) | Beurre (unit, theo 0)
A6: Creme patissier | B6: 17 kg | C6: doublon | D6: CREME PATISSIERE (kg, theo 20) | Creme patissiere (kg, theo 15)
A7: Poudre cacao | B7: 3 kg | C7: doublon / faute de frappe en base | D7: Cacao en poudre 10/12 (kg, theo 7,3) | Pouder cacao (kg, theo 0)
A8: Praline amande | B8: 8 kg | C8: doublon | D8: Praline amande (kg, theo 24) | Praline amande 50% (kg, theo 20,3) | Praline amande (unit, theo 0)
A9: Chocovic | B9: 9 kg | C9: libelle du carnet non trouve tel quel | D9: Beurre de cacao chocovic (kg, theo 3) -- a confirmer
A10: Tablette Signature blanc | B10: 2 kg | C10: doublon | D10: TABLETTE SIGNATURE BLANC (kg, theo 0) | Tablette Signature Blanc VHP (kg, theo 9,5)
A11: Batons boulanger | B11: 6 boites | C11: doublon + conversion boite -> unite inconnue | D11: 500 batons boulangers DGF (unit, theo 21) | Batons boulangers DGF 500 (unit, theo 0)
A12: Ameliorant viennoiserie | B12: 5 seaux | C12: poids du seau non renseigne en base | D12: Ameliorant Viennoiserie (kg, theo 0) -- indiquer les kg par seau
A13: Tegrale neutre | B13: 9 kg | C13: ABSENT du referentiel | D13: existent : Tegral multigrain (10) | Tegral vanille (16) | Tegral chocolat (15,9)
A14: Gelatine | B14: 1 boite | C14: 3 articles + conversion boite inconnue | D14: Gelatine en feuille (kg, theo 2) | Gelatine (unit, theo 1) | Gelatine en feuille (kg, theo 0)
A15: Chocolat couverture VAN - blanc | B15: 2,5 kg (chiffre rature) | C15: 'VAN' = 'VHP' ? a confirmer | D15: CHOCOLAT COUVERTURE BLANC VHP (kg, theo 5)
A16: Chocolat couverture VAN - noir | B16: 5 kg | C16: 'VAN' = 'VHP' ? + doublon | D16: CHOCOLAT DE COUVERTURE NOIR VHP (kg, theo 5) | Chocolat couverture noir VHP (kg, theo 3,847)
... A25: Lait | B25: 37 L | C25: doublon | D25: Lait (l, theo 261) | Lait (l, theo 6)

Sheet Synthese
A1: SYNTHESE DE L'INVENTAIRE
A2: Se met a jour automatiquement a partir des onglets de comptage.
A4: Famille | B4: Source | C4: Nb articles | D4: Valeur theorique | E4: Valeur comptee | F4: Valeur ecart | G4: % ecart
A5: Matières premières | B5: Ingredients | C5: =COUNTIF(Ingredients!$B$7:$B$381,$A5) | D5: =SUMPRODUCT((Ingredients!$B$7:$B$381=$A5)*Ingredients!$I$7:$I$381*Ingredients!$N$7:$N$381) | E5: =SUMIF(Ingredients!$B$7:$B$381,$A5,Ingredients!$O$7:$O$381) | F5: =SUMIF(Ingredients!$B$7:$B$381,$A5,Ingredients!$P$7:$P$381) | G5: =IF($D5=0,0,$F5/$D5)
A6: Équipements & Matériel | B6: Ingredients | C6: =COUNTIF(Ingredients!$B$7:$B$381,$A6) | D6: =SUMPRODUCT((Ingredients!$B$7:$B$381=$A6)*Ingredients!$I$7:$I$381*Ingredients!$N$7:$N$381) | E6: =SUMIF(Ingredients!$B$7:$B$381,$A6,Ingredients!$O$7:$O$381) | F6: =SUMIF(Ingredients!$B$7:$B$381,$A6,Ingredients!$P$7:$P$381) | G6: =IF($D6=0,0,$F6/$D6)
A7: Emballages | B7: Consommables | C7: =COUNTIF(Consommables!$B$7:$B$115,$A7) | D7: =SUMPRODUCT((Consommables!$B$7:$B$115=$A7)*Consommables!$H$7:$H$115*Consommables!$K$7:$K$115) | E7: =SUMIF(Consommables!$B$7:$B$115,$A7,Consommables!$L$7:$L$115) | F7: =SUMIF(Consommables!$B$7:$B$115,$A7,Consommables!$M$7:$M$115) | G7: =IF($D7=0,0,$F7/$D7)
A8: Entretien & Maintenance | B8: Consommables | C8: =COUNTIF(Consommables!$B$7:$B$115,$A8) | D8: =SUMPRODUCT((Consommables!$B$7:$B$115=$A8)*Consommables!$H$7:$H$115*Consommables!$K$7:$K$115) | E8: =SUMIF(Consommables!$B$7:$B$115,$A8,Consommables!$L$7:$L$115) | F8: =SUMIF(Consommables!$B$7:$B$115,$A8,Consommables!$M$7:$M$115) | G8: =IF($D8=0,0,$F8/$D8)
A9: Non classe (a rattacher) | B9: Consommables | C9: =COUNTIF(Consommables!$B$7:$B$115,$A9) | D9: =SUMPRODUCT((Consommables!$B$7:$B$115=$A9)*Consommables!$H$7:$H$115*Consommables!$K$7:$K$115) | E9: =SUMIF(Consommables!$B$7:$B$115,$A9,Consommables!$L$7:$L$115) | F9: =SUMIF(Consommables!$B$7:$B$115,$A9,Consommables!$M$7:$M$115) | G9: =IF($D9=0,0,$F9/$D9)
A10: Équipements & Matériel | B10: Consommables | C10: =COUNTIF(Consommables!$B$7:$B$115,$A10) | D10: =SUMPRODUCT((Consommables!$B$7:$B$115=$A10)*Consommables!$H$7:$H$115*Consommables!$K$7:$K$115) | E10: =SUMIF(Consommables!$B$7:$B$115,$A10,Consommables!$L$7:$L$115) | F10: =SUMIF(Consommables!$B$7:$B$115,$A10,Consommables!$M$7:$M$115) | G10: =IF($D10=0,0,$F10/$D10)
A11: TOTAL GENERAL | C11: =SUM(C5:C10) | D11: =SUM(D5:D10) | E11: =SUM(E5:E10) | F11: =SUM(F5:F10) | G11: =IF($D11=0,0,$F11/$D11)
A14: Signatures
A15: Magasinier / compteur
A16: Responsable production
A17: Direction / comptabilite
